<robot xmlns:xacro="http://www.ros.org/wiki/xacro" name="robotis_op3" >
  <xacro:include filename="$(find robotis_description)/robots/robotis_op3.urdf" />

  <!--
  <gazebo reference="l_foot_link">
    <kp>500000.0</kp>
    <kd>10.0</kd>
    <mu1>10</mu1>
    <mu2>10</mu2>
    <fdir1>1 0 0</fdir1>
    <maxVel>0.1</maxVel>
    <minDepth>0.001</minDepth>
  </gazebo>
  <gazebo reference="r_foot_link">
    <kp>500000.0</kp>
    <kd>10.0</kd>
    <mu1>10</mu1>
    <mu2>10</mu2>
    <fdir1>1 0 0</fdir1>
    <maxVel>0.1</maxVel>
    <minDepth>0.001</minDepth>
  </gazebo>
  -->

  <gazebo reference="l_foot_link">
    <kp>100000.0</kp>
    <kd>10.0</kd>
    <mu1>5.0</mu1>
    <mu2>5.0</mu2>
    <fdir1>1 0 0</fdir1>
    <maxVel>1.0</maxVel>
    <minDepth>0.00</minDepth>
  </gazebo>
  <gazebo reference="r_foot_link">
    <kp>100000.0</kp>
    <kd>10.0</kd>
    <mu1>5.0</mu1>
    <mu2>5.0</mu2>
    <fdir1>1 0 0</fdir1>
    <maxVel>1.0</maxVel>
    <minDepth>0.00</minDepth>
  </gazebo>

  <gazebo reference="l_hip_yaw">
    <implicitSpringDamper>1</implicitSpringDamper>
  </gazebo>
  <gazebo reference="l_hip_roll">
    <implicitSpringDamper>1</implicitSpringDamper>
  </gazebo>
  <gazebo reference="l_hip_pitch">
    <implicitSpringDamper>1</implicitSpringDamper>
  </gazebo>
  <gazebo reference="l_knee">
    <implicitSpringDamper>1</implicitSpringDamper>
  </gazebo>
  <gazebo reference="l_ank_roll">
    <implicitSpringDamper>1</implicitSpringDamper>
  </gazebo>
  <gazebo reference="l_ank_pitch">
    <implicitSpringDamper>1</implicitSpringDamper>
  </gazebo>
  <gazebo reference="r_hip_yaw">
    <implicitSpringDamper>1</implicitSpringDamper>
  </gazebo>
  <gazebo reference="r_hip_roll">
    <implicitSpringDamper>1</implicitSpringDamper>
  </gazebo>
  <gazebo reference="r_hip_pitch">
    <implicitSpringDamper>1</implicitSpringDamper>
  </gazebo>
  <gazebo reference="r_knee">
    <implicitSpringDamper>1</implicitSpringDamper>
  </gazebo>
  <gazebo reference="r_ank_roll">
    <implicitSpringDamper>1</implicitSpringDamper>
  </gazebo>
  <gazebo reference="r_ank_pitch">
    <implicitSpringDamper>1</implicitSpringDamper>
  </gazebo>

  <!-- Load the plugin -->
  <gazebo>
    <plugin name="robotis_gazebo_plugin" filename="librobotis_gazebo_plugin.so"/>
  </gazebo>

  <!-- Add harness joint -->
  <gazebo>
    <plugin filename="libgazebo_ros_harness.so" name="harness">
      <joint name="harness_joint" type="prismatic">
        <pose>0 0 0 0 0 0</pose>
        <parent>world</parent>
        <child>body_link</child>
        <axis>
          <xyz>0 0 1</xyz>
          <dynamics>
            <damping>10</damping>
          </dynamics>
          <limit>
            <lower>-0.1</lower>
            <upper>0.1</upper>
            <effort>10000</effort>
            <velocity>-1</velocity>
            <stiffness>0</stiffness>
            <dissipation>0</dissipation>
          </limit>
        </axis>
        <physics>
          <ode>
            <implicit_spring_damper>1</implicit_spring_damper>
            <limit>
              <cfm>0.0</cfm>
              <erp>0.0</erp>
            </limit>
          </ode>
        </physics>
      </joint>
      <winch>
        <joint>harness_joint</joint>
        <pos_pid>
          <p>4e3</p>
          <i>0</i>
          <d>0</d>
          <i_min>0</i_min>
          <i_max>0</i_max>
          <cmd_min>-1e4</cmd_min>
          <cmd_max>1e4</cmd_max>
        </pos_pid>
        <vel_pid>
          <p>4e3</p>
          <i>0</i>
          <d>0</d>
          <i_min>0</i_min>
          <i_max>0</i_max>
          <cmd_min>0</cmd_min>
          <cmd_max>1e4</cmd_max>
        </vel_pid>
      </winch>
      <detach>harness_joint</detach>
    </plugin>
  </gazebo>

  <!-- Add left foot's ft sensor plugin -->
  <gazebo reference="l_leg_ft">
    <provideFeedback>true</provideFeedback>
  </gazebo>
  <gazebo>
    <plugin name="ft_sensor" filename="libgazebo_ros_ft_sensor.so">
      <updateRate>100.0</updateRate>
      <topicName>/robotis/sensor/ft/l_foot</topicName>
      <jointName>l_leg_ft</jointName>
    </plugin>
  </gazebo>

  <!-- Add right foot's ft sensor plugin -->
  <gazebo reference="r_leg_ft">
    <provideFeedback>true</provideFeedback>
  </gazebo>
  <gazebo>
    <plugin name="ft_sensor" filename="libgazebo_ros_ft_sensor.so">
      <updateRate>100.0</updateRate>
      <topicName>/robotis/sensor/ft/r_foot</topicName>
      <jointName>r_leg_ft</jointName>
    </plugin>
  </gazebo>

  <!-- Add imu plugin -->
  <gazebo>
    <plugin name="imu_plugin" filename="libgazebo_ros_imu.so">
      <alwaysOn>true</alwaysOn>
      <bodyName>imu_link</bodyName>
      <topicName>/robotis/sensor/imu</topicName>
      <serviceName>/robotis/sensor/imu_service</serviceName>
      <gaussianNoise>0.0</gaussianNoise>
      <updateRate>100.0</updateRate>
      <imu>
        <noise>
          <type>gaussian</type>
          <rate>
            <mean>0.0</mean>
            <stddev>2e-4</stddev>
            <bias_mean>0.0000075</bias_mean>
            <bias_stddev>0.0000008</bias_stddev>
          </rate>
          <accel>
            <mean>0.0</mean>
            <stddev>1.7e-2</stddev>
            <bias_mean>0.1</bias_mean>
            <bias_stddev>0.001</bias_stddev>
          </accel>
        </noise>
      </imu>
    </plugin>
  </gazebo>

</robot>
